<?xml version="1.0" ?>

<robot name="mrm" xmlns:xacro="http://www.ros.org/wiki/xacro">

    <material name="blue">
        <color rgba="0 0 0.8 1"/>
    </material>

    <material name="black">
        <color rgba="0 0 0 1"/>
    </material>
    
    <material name="white">
        <color rgba="1 1 1 1"/>
    </material>

    <link name="base_link">
        <visual>
            <origin rpy="0 0 0" xyz="0 0 0"/>
            <geometry>
                <box size="1.5 1.5 1.5"/>
            </geometry>
        </visual>
    </link>
    
    <joint name="joint_1" type="revolute">
        <axis xyz="0 0 1" />
        <limit effort="1000.0" lower="-3.14" upper="3.14" velocity="0.5" />
        <origin rpy="0 0 0" xyz="0 0 0.5"/>
        <parent link="base_link"/>
        <child link="link1"/>
    </joint>
    
    <link name="link1">
        <visual>
            <origin rpy="0 0 0" xyz="0 0 0.2"/>
            <geometry>
                <cylinder radius="0.35" length="2"/>
            </geometry>
            <material name="white"/>
        </visual>
    </link>

    <joint name="joint_2" type="prismatic">
        <axis xyz="0 0 1" />
        <limit effort="1000.0" lower="-0.5" upper="0.5" velocity="0.5" />
        <origin rpy="0 0 0" xyz="0 0 0.5"/>
        <parent link="link1"/>
        <child link="link2"/>
    </joint>

    <link name="link2">
        <visual>
            <origin rpy="0 0 0" xyz="0 0 0.7"/>
            <geometry>
                <cylinder radius="0.2" length="1.5"/>
            </geometry>
            <material name="blue"/>
        </visual>
    </link>

    <joint name="joint_3" type="fixed">
        <axis xyz="0 0 1" />
        <origin rpy="0 0 0" xyz="0 0 0.5"/>
        <parent link="link2"/>
        <child link="link3"/>
    </joint>

    <link name="link3">
        <visual>
            <origin rpy="0 0 0" xyz="0 0 1"/>
            <geometry>
                <box size="0.5 0.5 0.5"/>
            </geometry>
            <material name="black"/>
        </visual>
    </link>
</robot>